[2023-09-08 16:21:42 +0000] [2135797] [INFO] Starting gunicorn 21.2.0
[2023-09-08 16:21:42 +0000] [2135797] [INFO] Listening at: http://0.0.0.0:5000 (2135797)
[2023-09-08 16:21:42 +0000] [2135797] [INFO] Using worker: sync
[2023-09-08 16:21:42 +0000] [2135798] [INFO] Booting worker with pid: 2135798
[2023-09-08 16:21:42 +0000] [2135798] [ERROR] Exception in worker process
Traceback (most recent call last):
  File "/home/ec2-user/.local/lib/python3.9/site-packages/gunicorn/arbiter.py", line 609, in spawn_worker
    worker.init_process()
  File "/home/ec2-user/.local/lib/python3.9/site-packages/gunicorn/workers/base.py", line 134, in init_process
    self.load_wsgi()
  File "/home/ec2-user/.local/lib/python3.9/site-packages/gunicorn/workers/base.py", line 146, in load_wsgi
    self.wsgi = self.app.wsgi()
  File "/home/ec2-user/.local/lib/python3.9/site-packages/gunicorn/app/base.py", line 67, in wsgi
    self.callable = self.load()
  File "/home/ec2-user/.local/lib/python3.9/site-packages/gunicorn/app/wsgiapp.py", line 58, in load
    return self.load_wsgiapp()
  File "/home/ec2-user/.local/lib/python3.9/site-packages/gunicorn/app/wsgiapp.py", line 48, in load_wsgiapp
    return util.import_app(self.app_uri)
  File "/home/ec2-user/.local/lib/python3.9/site-packages/gunicorn/util.py", line 371, in import_app
    mod = importlib.import_module(module)
  File "/usr/lib64/python3.9/importlib/__init__.py", line 127, in import_module
    return _bootstrap._gcd_import(name[level:], package, level)
  File "<frozen importlib._bootstrap>", line 1030, in _gcd_import
  File "<frozen importlib._bootstrap>", line 1007, in _find_and_load
  File "<frozen importlib._bootstrap>", line 984, in _find_and_load_unlocked
ModuleNotFoundError: No module named 'app'
[2023-09-08 16:21:42 +0000] [2135798] [INFO] Worker exiting (pid: 2135798)
[2023-09-08 16:21:42 +0000] [2135797] [ERROR] Worker (pid:2135798) exited with code 3
[2023-09-08 16:21:42 +0000] [2135797] [ERROR] Shutting down: Master
[2023-09-08 16:21:42 +0000] [2135797] [ERROR] Reason: Worker failed to boot.
[2023-09-08 16:22:15 +0000] [2135802] [INFO] Starting gunicorn 21.2.0
[2023-09-08 16:22:15 +0000] [2135802] [INFO] Listening at: http://0.0.0.0:5000 (2135802)
[2023-09-08 16:22:15 +0000] [2135802] [INFO] Using worker: sync
[2023-09-08 16:22:15 +0000] [2135803] [INFO] Booting worker with pid: 2135803
[2023-09-08 16:22:15 +0000] [2135803] [ERROR] Exception in worker process
Traceback (most recent call last):
  File "/home/ec2-user/.local/lib/python3.9/site-packages/gunicorn/arbiter.py", line 609, in spawn_worker
    worker.init_process()
  File "/home/ec2-user/.local/lib/python3.9/site-packages/gunicorn/workers/base.py", line 134, in init_process
    self.load_wsgi()
  File "/home/ec2-user/.local/lib/python3.9/site-packages/gunicorn/workers/base.py", line 146, in load_wsgi
    self.wsgi = self.app.wsgi()
  File "/home/ec2-user/.local/lib/python3.9/site-packages/gunicorn/app/base.py", line 67, in wsgi
    self.callable = self.load()
  File "/home/ec2-user/.local/lib/python3.9/site-packages/gunicorn/app/wsgiapp.py", line 58, in load
    return self.load_wsgiapp()
  File "/home/ec2-user/.local/lib/python3.9/site-packages/gunicorn/app/wsgiapp.py", line 48, in load_wsgiapp
    return util.import_app(self.app_uri)
  File "/home/ec2-user/.local/lib/python3.9/site-packages/gunicorn/util.py", line 371, in import_app
    mod = importlib.import_module(module)
  File "/usr/lib64/python3.9/importlib/__init__.py", line 127, in import_module
    return _bootstrap._gcd_import(name[level:], package, level)
  File "<frozen importlib._bootstrap>", line 1030, in _gcd_import
  File "<frozen importlib._bootstrap>", line 1007, in _find_and_load
  File "<frozen importlib._bootstrap>", line 984, in _find_and_load_unlocked
ModuleNotFoundError: No module named 'app'
[2023-09-08 16:22:15 +0000] [2135803] [INFO] Worker exiting (pid: 2135803)
[2023-09-08 16:22:15 +0000] [2135802] [ERROR] Worker (pid:2135803) exited with code 3
[2023-09-08 16:22:15 +0000] [2135802] [ERROR] Shutting down: Master
[2023-09-08 16:22:15 +0000] [2135802] [ERROR] Reason: Worker failed to boot.
